ERROR 2024-10-04 21:30:31,793 log Internal Server Error: /payment/
Traceback (most recent call last):
  File "C:\Users\seraj\.virtualenvs\ml_project-fwWSGRpw\Lib\site-packages\django\db\models\fields\__init__.py", line 2761, in to_python
    return uuid.UUID(**{input_form: value})
           ^^^^^^^^^^^^^^^^^^^^^^^^^^^^^^^^
  File "C:\Users\seraj\AppData\Local\Programs\Python\Python312\Lib\uuid.py", line 178, in __init__
    raise ValueError('badly formed hexadecimal UUID string')
ValueError: badly formed hexadecimal UUID string

During handling of the above exception, another exception occurred:

Traceback (most recent call last):
  File "C:\Users\seraj\.virtualenvs\ml_project-fwWSGRpw\Lib\site-packages\django\core\handlers\exception.py", line 55, in inner
    response = get_response(request)
               ^^^^^^^^^^^^^^^^^^^^^
  File "C:\Users\seraj\.virtualenvs\ml_project-fwWSGRpw\Lib\site-packages\django\core\handlers\base.py", line 197, in _get_response
    response = wrapped_callback(request, *callback_args, **callback_kwargs)
               ^^^^^^^^^^^^^^^^^^^^^^^^^^^^^^^^^^^^^^^^^^^^^^^^^^^^^^^^^^^^
  File "C:\Users\seraj\.virtualenvs\ml_project-fwWSGRpw\Lib\site-packages\django\views\decorators\csrf.py", line 65, in _view_wrapper
    return view_func(request, *args, **kwargs)
           ^^^^^^^^^^^^^^^^^^^^^^^^^^^^^^^^^^^
  File "C:\Users\seraj\.virtualenvs\ml_project-fwWSGRpw\Lib\site-packages\django\views\generic\base.py", line 104, in view
    return self.dispatch(request, *args, **kwargs)
           ^^^^^^^^^^^^^^^^^^^^^^^^^^^^^^^^^^^^^^^
  File "C:\Users\seraj\.virtualenvs\ml_project-fwWSGRpw\Lib\site-packages\rest_framework\views.py", line 509, in dispatch
    response = self.handle_exception(exc)
               ^^^^^^^^^^^^^^^^^^^^^^^^^^
  File "C:\Users\seraj\.virtualenvs\ml_project-fwWSGRpw\Lib\site-packages\rest_framework\views.py", line 469, in handle_exception
    self.raise_uncaught_exception(exc)
  File "C:\Users\seraj\.virtualenvs\ml_project-fwWSGRpw\Lib\site-packages\rest_framework\views.py", line 480, in raise_uncaught_exception
    raise exc
  File "C:\Users\seraj\.virtualenvs\ml_project-fwWSGRpw\Lib\site-packages\rest_framework\views.py", line 506, in dispatch
    response = handler(request, *args, **kwargs)
               ^^^^^^^^^^^^^^^^^^^^^^^^^^^^^^^^^
  File "C:\Users\seraj\.virtualenvs\ml_project-fwWSGRpw\Lib\site-packages\rest_framework\decorators.py", line 50, in handler
    return func(*args, **kwargs)
           ^^^^^^^^^^^^^^^^^^^^^
  File "C:\Users\seraj\OneDrive\Desktop\gym_management1\payment\views.py", line 146, in create_checkout_session
    product = get_object_or_404(GymProducts, id=product_id)
              ^^^^^^^^^^^^^^^^^^^^^^^^^^^^^^^^^^^^^^^^^^^^^
  File "C:\Users\seraj\.virtualenvs\ml_project-fwWSGRpw\Lib\site-packages\django\shortcuts.py", line 86, in get_object_or_404
    return queryset.get(*args, **kwargs)
           ^^^^^^^^^^^^^^^^^^^^^^^^^^^^^
  File "C:\Users\seraj\.virtualenvs\ml_project-fwWSGRpw\Lib\site-packages\django\db\models\query.py", line 635, in get
    clone = self._chain() if self.query.combinator else self.filter(*args, **kwargs)
                                                        ^^^^^^^^^^^^^^^^^^^^^^^^^^^^
  File "C:\Users\seraj\.virtualenvs\ml_project-fwWSGRpw\Lib\site-packages\django\db\models\query.py", line 1476, in filter
    return self._filter_or_exclude(False, args, kwargs)
           ^^^^^^^^^^^^^^^^^^^^^^^^^^^^^^^^^^^^^^^^^^^^
  File "C:\Users\seraj\.virtualenvs\ml_project-fwWSGRpw\Lib\site-packages\django\db\models\query.py", line 1494, in _filter_or_exclude
    clone._filter_or_exclude_inplace(negate, args, kwargs)
  File "C:\Users\seraj\.virtualenvs\ml_project-fwWSGRpw\Lib\site-packages\django\db\models\query.py", line 1501, in _filter_or_exclude_inplace
    self._query.add_q(Q(*args, **kwargs))
  File "C:\Users\seraj\.virtualenvs\ml_project-fwWSGRpw\Lib\site-packages\django\db\models\sql\query.py", line 1609, in add_q
    clause, _ = self._add_q(q_object, self.used_aliases)
                ^^^^^^^^^^^^^^^^^^^^^^^^^^^^^^^^^^^^^^^^
  File "C:\Users\seraj\.virtualenvs\ml_project-fwWSGRpw\Lib\site-packages\django\db\models\sql\query.py", line 1641, in _add_q
    child_clause, needed_inner = self.build_filter(
                                 ^^^^^^^^^^^^^^^^^^
  File "C:\Users\seraj\.virtualenvs\ml_project-fwWSGRpw\Lib\site-packages\django\db\models\sql\query.py", line 1555, in build_filter
    condition = self.build_lookup(lookups, col, value)
                ^^^^^^^^^^^^^^^^^^^^^^^^^^^^^^^^^^^^^^
  File "C:\Users\seraj\.virtualenvs\ml_project-fwWSGRpw\Lib\site-packages\django\db\models\sql\query.py", line 1385, in build_lookup
    lookup = lookup_class(lhs, rhs)
             ^^^^^^^^^^^^^^^^^^^^^^
  File "C:\Users\seraj\.virtualenvs\ml_project-fwWSGRpw\Lib\site-packages\django\db\models\lookups.py", line 30, in __init__
    self.rhs = self.get_prep_lookup()
               ^^^^^^^^^^^^^^^^^^^^^^
  File "C:\Users\seraj\.virtualenvs\ml_project-fwWSGRpw\Lib\site-packages\django\db\models\lookups.py", line 369, in get_prep_lookup
    return super().get_prep_lookup()
           ^^^^^^^^^^^^^^^^^^^^^^^^^
  File "C:\Users\seraj\.virtualenvs\ml_project-fwWSGRpw\Lib\site-packages\django\db\models\lookups.py", line 88, in get_prep_lookup
    return self.lhs.output_field.get_prep_value(self.rhs)
           ^^^^^^^^^^^^^^^^^^^^^^^^^^^^^^^^^^^^^^^^^^^^^^
  File "C:\Users\seraj\.virtualenvs\ml_project-fwWSGRpw\Lib\site-packages\django\db\models\fields\__init__.py", line 2745, in get_prep_value
    return self.to_python(value)
           ^^^^^^^^^^^^^^^^^^^^^
  File "C:\Users\seraj\.virtualenvs\ml_project-fwWSGRpw\Lib\site-packages\django\db\models\fields\__init__.py", line 2763, in to_python
    raise exceptions.ValidationError(
django.core.exceptions.ValidationError: ['“string” is not a valid UUID.']
ERROR 2024-10-04 21:30:32,076 basehttp "POST /payment/ HTTP/1.1" 500 145
ERROR 2024-10-04 21:32:47,727 log Internal Server Error: /payment/payment-success/
Traceback (most recent call last):
  File "C:\Users\seraj\.virtualenvs\ml_project-fwWSGRpw\Lib\site-packages\django\db\backends\utils.py", line 105, in _execute
    return self.cursor.execute(sql, params)
           ^^^^^^^^^^^^^^^^^^^^^^^^^^^^^^^^
  File "C:\Users\seraj\.virtualenvs\ml_project-fwWSGRpw\Lib\site-packages\django\db\backends\sqlite3\base.py", line 354, in execute
    return super().execute(query, params)
           ^^^^^^^^^^^^^^^^^^^^^^^^^^^^^^
sqlite3.IntegrityError: NOT NULL constraint failed: payment_payment.stripe_payment_id

The above exception was the direct cause of the following exception:

Traceback (most recent call last):
  File "C:\Users\seraj\.virtualenvs\ml_project-fwWSGRpw\Lib\site-packages\django\core\handlers\exception.py", line 55, in inner
    response = get_response(request)
               ^^^^^^^^^^^^^^^^^^^^^
  File "C:\Users\seraj\.virtualenvs\ml_project-fwWSGRpw\Lib\site-packages\django\core\handlers\base.py", line 197, in _get_response
    response = wrapped_callback(request, *callback_args, **callback_kwargs)
               ^^^^^^^^^^^^^^^^^^^^^^^^^^^^^^^^^^^^^^^^^^^^^^^^^^^^^^^^^^^^
  File "C:\Users\seraj\OneDrive\Desktop\gym_management1\payment\views.py", line 294, in payment_success
    payment = Payment.objects.create(
              ^^^^^^^^^^^^^^^^^^^^^^^
  File "C:\Users\seraj\.virtualenvs\ml_project-fwWSGRpw\Lib\site-packages\django\db\models\manager.py", line 87, in manager_method
    return getattr(self.get_queryset(), name)(*args, **kwargs)
           ^^^^^^^^^^^^^^^^^^^^^^^^^^^^^^^^^^^^^^^^^^^^^^^^^^^
  File "C:\Users\seraj\.virtualenvs\ml_project-fwWSGRpw\Lib\site-packages\django\db\models\query.py", line 679, in create
    obj.save(force_insert=True, using=self.db)
  File "C:\Users\seraj\.virtualenvs\ml_project-fwWSGRpw\Lib\site-packages\django\db\models\base.py", line 891, in save
    self.save_base(
  File "C:\Users\seraj\.virtualenvs\ml_project-fwWSGRpw\Lib\site-packages\django\db\models\base.py", line 997, in save_base
    updated = self._save_table(
              ^^^^^^^^^^^^^^^^^
  File "C:\Users\seraj\.virtualenvs\ml_project-fwWSGRpw\Lib\site-packages\django\db\models\base.py", line 1160, in _save_table
    results = self._do_insert(
              ^^^^^^^^^^^^^^^^
  File "C:\Users\seraj\.virtualenvs\ml_project-fwWSGRpw\Lib\site-packages\django\db\models\base.py", line 1201, in _do_insert
    return manager._insert(
           ^^^^^^^^^^^^^^^^
  File "C:\Users\seraj\.virtualenvs\ml_project-fwWSGRpw\Lib\site-packages\django\db\models\manager.py", line 87, in manager_method
    return getattr(self.get_queryset(), name)(*args, **kwargs)
           ^^^^^^^^^^^^^^^^^^^^^^^^^^^^^^^^^^^^^^^^^^^^^^^^^^^
  File "C:\Users\seraj\.virtualenvs\ml_project-fwWSGRpw\Lib\site-packages\django\db\models\query.py", line 1847, in _insert
    return query.get_compiler(using=using).execute_sql(returning_fields)
           ^^^^^^^^^^^^^^^^^^^^^^^^^^^^^^^^^^^^^^^^^^^^^^^^^^^^^^^^^^^^^
  File "C:\Users\seraj\.virtualenvs\ml_project-fwWSGRpw\Lib\site-packages\django\db\models\sql\compiler.py", line 1836, in execute_sql
    cursor.execute(sql, params)
  File "C:\Users\seraj\.virtualenvs\ml_project-fwWSGRpw\Lib\site-packages\django\db\backends\utils.py", line 79, in execute
    return self._execute_with_wrappers(
           ^^^^^^^^^^^^^^^^^^^^^^^^^^^^
  File "C:\Users\seraj\.virtualenvs\ml_project-fwWSGRpw\Lib\site-packages\django\db\backends\utils.py", line 92, in _execute_with_wrappers
    return executor(sql, params, many, context)
           ^^^^^^^^^^^^^^^^^^^^^^^^^^^^^^^^^^^^
  File "C:\Users\seraj\.virtualenvs\ml_project-fwWSGRpw\Lib\site-packages\django\db\backends\utils.py", line 100, in _execute
    with self.db.wrap_database_errors:
  File "C:\Users\seraj\.virtualenvs\ml_project-fwWSGRpw\Lib\site-packages\django\db\utils.py", line 91, in __exit__
    raise dj_exc_value.with_traceback(traceback) from exc_value
  File "C:\Users\seraj\.virtualenvs\ml_project-fwWSGRpw\Lib\site-packages\django\db\backends\utils.py", line 105, in _execute
    return self.cursor.execute(sql, params)
           ^^^^^^^^^^^^^^^^^^^^^^^^^^^^^^^^
  File "C:\Users\seraj\.virtualenvs\ml_project-fwWSGRpw\Lib\site-packages\django\db\backends\sqlite3\base.py", line 354, in execute
    return super().execute(query, params)
           ^^^^^^^^^^^^^^^^^^^^^^^^^^^^^^
django.db.utils.IntegrityError: NOT NULL constraint failed: payment_payment.stripe_payment_id
ERROR 2024-10-04 21:32:47,805 basehttp "GET /payment/payment-success/?session_id=cs_test_a1pNiC0kG54GcEX3HBfw4elWfX6EBFirPaAIVaSoWumkOW6DOOVZaQoVU4 HTTP/1.1" 500 145
ERROR 2024-10-04 21:33:12,610 log Internal Server Error: /payment/payment-success/
Traceback (most recent call last):
  File "C:\Users\seraj\.virtualenvs\ml_project-fwWSGRpw\Lib\site-packages\django\db\backends\utils.py", line 105, in _execute
    return self.cursor.execute(sql, params)
           ^^^^^^^^^^^^^^^^^^^^^^^^^^^^^^^^
  File "C:\Users\seraj\.virtualenvs\ml_project-fwWSGRpw\Lib\site-packages\django\db\backends\sqlite3\base.py", line 354, in execute
    return super().execute(query, params)
           ^^^^^^^^^^^^^^^^^^^^^^^^^^^^^^
sqlite3.IntegrityError: NOT NULL constraint failed: payment_payment.stripe_payment_id

The above exception was the direct cause of the following exception:

Traceback (most recent call last):
  File "C:\Users\seraj\.virtualenvs\ml_project-fwWSGRpw\Lib\site-packages\django\core\handlers\exception.py", line 55, in inner
    response = get_response(request)
               ^^^^^^^^^^^^^^^^^^^^^
  File "C:\Users\seraj\.virtualenvs\ml_project-fwWSGRpw\Lib\site-packages\django\core\handlers\base.py", line 197, in _get_response
    response = wrapped_callback(request, *callback_args, **callback_kwargs)
               ^^^^^^^^^^^^^^^^^^^^^^^^^^^^^^^^^^^^^^^^^^^^^^^^^^^^^^^^^^^^
  File "C:\Users\seraj\OneDrive\Desktop\gym_management1\payment\views.py", line 294, in payment_success
    payment = Payment.objects.create(
              ^^^^^^^^^^^^^^^^^^^^^^^
  File "C:\Users\seraj\.virtualenvs\ml_project-fwWSGRpw\Lib\site-packages\django\db\models\manager.py", line 87, in manager_method
    return getattr(self.get_queryset(), name)(*args, **kwargs)
           ^^^^^^^^^^^^^^^^^^^^^^^^^^^^^^^^^^^^^^^^^^^^^^^^^^^
  File "C:\Users\seraj\.virtualenvs\ml_project-fwWSGRpw\Lib\site-packages\django\db\models\query.py", line 679, in create
    obj.save(force_insert=True, using=self.db)
  File "C:\Users\seraj\.virtualenvs\ml_project-fwWSGRpw\Lib\site-packages\django\db\models\base.py", line 891, in save
    self.save_base(
  File "C:\Users\seraj\.virtualenvs\ml_project-fwWSGRpw\Lib\site-packages\django\db\models\base.py", line 997, in save_base
    updated = self._save_table(
              ^^^^^^^^^^^^^^^^^
  File "C:\Users\seraj\.virtualenvs\ml_project-fwWSGRpw\Lib\site-packages\django\db\models\base.py", line 1160, in _save_table
    results = self._do_insert(
              ^^^^^^^^^^^^^^^^
  File "C:\Users\seraj\.virtualenvs\ml_project-fwWSGRpw\Lib\site-packages\django\db\models\base.py", line 1201, in _do_insert
    return manager._insert(
           ^^^^^^^^^^^^^^^^
  File "C:\Users\seraj\.virtualenvs\ml_project-fwWSGRpw\Lib\site-packages\django\db\models\manager.py", line 87, in manager_method
    return getattr(self.get_queryset(), name)(*args, **kwargs)
           ^^^^^^^^^^^^^^^^^^^^^^^^^^^^^^^^^^^^^^^^^^^^^^^^^^^
  File "C:\Users\seraj\.virtualenvs\ml_project-fwWSGRpw\Lib\site-packages\django\db\models\query.py", line 1847, in _insert
    return query.get_compiler(using=using).execute_sql(returning_fields)
           ^^^^^^^^^^^^^^^^^^^^^^^^^^^^^^^^^^^^^^^^^^^^^^^^^^^^^^^^^^^^^
  File "C:\Users\seraj\.virtualenvs\ml_project-fwWSGRpw\Lib\site-packages\django\db\models\sql\compiler.py", line 1836, in execute_sql
    cursor.execute(sql, params)
  File "C:\Users\seraj\.virtualenvs\ml_project-fwWSGRpw\Lib\site-packages\django\db\backends\utils.py", line 122, in execute
    return super().execute(sql, params)
           ^^^^^^^^^^^^^^^^^^^^^^^^^^^^
  File "C:\Users\seraj\.virtualenvs\ml_project-fwWSGRpw\Lib\site-packages\django\db\backends\utils.py", line 79, in execute
    return self._execute_with_wrappers(
           ^^^^^^^^^^^^^^^^^^^^^^^^^^^^
  File "C:\Users\seraj\.virtualenvs\ml_project-fwWSGRpw\Lib\site-packages\django\db\backends\utils.py", line 92, in _execute_with_wrappers
    return executor(sql, params, many, context)
           ^^^^^^^^^^^^^^^^^^^^^^^^^^^^^^^^^^^^
  File "C:\Users\seraj\.virtualenvs\ml_project-fwWSGRpw\Lib\site-packages\django\db\backends\utils.py", line 100, in _execute
    with self.db.wrap_database_errors:
  File "C:\Users\seraj\.virtualenvs\ml_project-fwWSGRpw\Lib\site-packages\django\db\utils.py", line 91, in __exit__
    raise dj_exc_value.with_traceback(traceback) from exc_value
  File "C:\Users\seraj\.virtualenvs\ml_project-fwWSGRpw\Lib\site-packages\django\db\backends\utils.py", line 105, in _execute
    return self.cursor.execute(sql, params)
           ^^^^^^^^^^^^^^^^^^^^^^^^^^^^^^^^
  File "C:\Users\seraj\.virtualenvs\ml_project-fwWSGRpw\Lib\site-packages\django\db\backends\sqlite3\base.py", line 354, in execute
    return super().execute(query, params)
           ^^^^^^^^^^^^^^^^^^^^^^^^^^^^^^
django.db.utils.IntegrityError: NOT NULL constraint failed: payment_payment.stripe_payment_id
ERROR 2024-10-04 21:33:12,626 basehttp "GET /payment/payment-success/?session_id=cs_test_a1pNiC0kG54GcEX3HBfw4elWfX6EBFirPaAIVaSoWumkOW6DOOVZaQoVU4 HTTP/1.1" 500 178192
ERROR 2024-10-04 21:37:22,436 log Internal Server Error: /payment/payment-success/
Traceback (most recent call last):
  File "C:\Users\seraj\.virtualenvs\ml_project-fwWSGRpw\Lib\site-packages\django\db\backends\utils.py", line 105, in _execute
    return self.cursor.execute(sql, params)
           ^^^^^^^^^^^^^^^^^^^^^^^^^^^^^^^^
  File "C:\Users\seraj\.virtualenvs\ml_project-fwWSGRpw\Lib\site-packages\django\db\backends\sqlite3\base.py", line 354, in execute
    return super().execute(query, params)
           ^^^^^^^^^^^^^^^^^^^^^^^^^^^^^^
sqlite3.IntegrityError: NOT NULL constraint failed: payment_payment.stripe_payment_id

The above exception was the direct cause of the following exception:

Traceback (most recent call last):
  File "C:\Users\seraj\.virtualenvs\ml_project-fwWSGRpw\Lib\site-packages\django\core\handlers\exception.py", line 55, in inner
    response = get_response(request)
               ^^^^^^^^^^^^^^^^^^^^^
  File "C:\Users\seraj\.virtualenvs\ml_project-fwWSGRpw\Lib\site-packages\django\core\handlers\base.py", line 197, in _get_response
    response = wrapped_callback(request, *callback_args, **callback_kwargs)
               ^^^^^^^^^^^^^^^^^^^^^^^^^^^^^^^^^^^^^^^^^^^^^^^^^^^^^^^^^^^^
  File "C:\Users\seraj\OneDrive\Desktop\gym_management1\payment\views.py", line 294, in payment_success
    payment = Payment.objects.create(
              ^^^^^^^^^^^^^^^^^^^^^^^
  File "C:\Users\seraj\.virtualenvs\ml_project-fwWSGRpw\Lib\site-packages\django\db\models\manager.py", line 87, in manager_method
    return getattr(self.get_queryset(), name)(*args, **kwargs)
           ^^^^^^^^^^^^^^^^^^^^^^^^^^^^^^^^^^^^^^^^^^^^^^^^^^^
  File "C:\Users\seraj\.virtualenvs\ml_project-fwWSGRpw\Lib\site-packages\django\db\models\query.py", line 679, in create
    obj.save(force_insert=True, using=self.db)
  File "C:\Users\seraj\.virtualenvs\ml_project-fwWSGRpw\Lib\site-packages\django\db\models\base.py", line 891, in save
    self.save_base(
  File "C:\Users\seraj\.virtualenvs\ml_project-fwWSGRpw\Lib\site-packages\django\db\models\base.py", line 997, in save_base
    updated = self._save_table(
              ^^^^^^^^^^^^^^^^^
  File "C:\Users\seraj\.virtualenvs\ml_project-fwWSGRpw\Lib\site-packages\django\db\models\base.py", line 1160, in _save_table
    results = self._do_insert(
              ^^^^^^^^^^^^^^^^
  File "C:\Users\seraj\.virtualenvs\ml_project-fwWSGRpw\Lib\site-packages\django\db\models\base.py", line 1201, in _do_insert
    return manager._insert(
           ^^^^^^^^^^^^^^^^
  File "C:\Users\seraj\.virtualenvs\ml_project-fwWSGRpw\Lib\site-packages\django\db\models\manager.py", line 87, in manager_method
    return getattr(self.get_queryset(), name)(*args, **kwargs)
           ^^^^^^^^^^^^^^^^^^^^^^^^^^^^^^^^^^^^^^^^^^^^^^^^^^^
  File "C:\Users\seraj\.virtualenvs\ml_project-fwWSGRpw\Lib\site-packages\django\db\models\query.py", line 1847, in _insert
    return query.get_compiler(using=using).execute_sql(returning_fields)
           ^^^^^^^^^^^^^^^^^^^^^^^^^^^^^^^^^^^^^^^^^^^^^^^^^^^^^^^^^^^^^
  File "C:\Users\seraj\.virtualenvs\ml_project-fwWSGRpw\Lib\site-packages\django\db\models\sql\compiler.py", line 1836, in execute_sql
    cursor.execute(sql, params)
  File "C:\Users\seraj\.virtualenvs\ml_project-fwWSGRpw\Lib\site-packages\django\db\backends\utils.py", line 122, in execute
    return super().execute(sql, params)
           ^^^^^^^^^^^^^^^^^^^^^^^^^^^^
  File "C:\Users\seraj\.virtualenvs\ml_project-fwWSGRpw\Lib\site-packages\django\db\backends\utils.py", line 79, in execute
    return self._execute_with_wrappers(
           ^^^^^^^^^^^^^^^^^^^^^^^^^^^^
  File "C:\Users\seraj\.virtualenvs\ml_project-fwWSGRpw\Lib\site-packages\django\db\backends\utils.py", line 92, in _execute_with_wrappers
    return executor(sql, params, many, context)
           ^^^^^^^^^^^^^^^^^^^^^^^^^^^^^^^^^^^^
  File "C:\Users\seraj\.virtualenvs\ml_project-fwWSGRpw\Lib\site-packages\django\db\backends\utils.py", line 100, in _execute
    with self.db.wrap_database_errors:
  File "C:\Users\seraj\.virtualenvs\ml_project-fwWSGRpw\Lib\site-packages\django\db\utils.py", line 91, in __exit__
    raise dj_exc_value.with_traceback(traceback) from exc_value
  File "C:\Users\seraj\.virtualenvs\ml_project-fwWSGRpw\Lib\site-packages\django\db\backends\utils.py", line 105, in _execute
    return self.cursor.execute(sql, params)
           ^^^^^^^^^^^^^^^^^^^^^^^^^^^^^^^^
  File "C:\Users\seraj\.virtualenvs\ml_project-fwWSGRpw\Lib\site-packages\django\db\backends\sqlite3\base.py", line 354, in execute
    return super().execute(query, params)
           ^^^^^^^^^^^^^^^^^^^^^^^^^^^^^^
django.db.utils.IntegrityError: NOT NULL constraint failed: payment_payment.stripe_payment_id
ERROR 2024-10-04 21:37:22,460 basehttp "GET /payment/payment-success/?session_id=cs_test_a12YO31cv34wi0UEZwY05DMJOV2TUCANmUvOvBq4wdny6ypWHusdpXTtBb HTTP/1.1" 500 178059
ERROR 2024-10-04 21:40:22,649 log Internal Server Error: /payment/payment-success/
Traceback (most recent call last):
  File "C:\Users\seraj\.virtualenvs\ml_project-fwWSGRpw\Lib\site-packages\django\db\backends\utils.py", line 105, in _execute
    return self.cursor.execute(sql, params)
           ^^^^^^^^^^^^^^^^^^^^^^^^^^^^^^^^
  File "C:\Users\seraj\.virtualenvs\ml_project-fwWSGRpw\Lib\site-packages\django\db\backends\sqlite3\base.py", line 354, in execute
    return super().execute(query, params)
           ^^^^^^^^^^^^^^^^^^^^^^^^^^^^^^
sqlite3.IntegrityError: NOT NULL constraint failed: payment_payment.stripe_payment_id

The above exception was the direct cause of the following exception:

Traceback (most recent call last):
  File "C:\Users\seraj\.virtualenvs\ml_project-fwWSGRpw\Lib\site-packages\django\core\handlers\exception.py", line 55, in inner
    response = get_response(request)
               ^^^^^^^^^^^^^^^^^^^^^
  File "C:\Users\seraj\.virtualenvs\ml_project-fwWSGRpw\Lib\site-packages\django\core\handlers\base.py", line 197, in _get_response
    response = wrapped_callback(request, *callback_args, **callback_kwargs)
               ^^^^^^^^^^^^^^^^^^^^^^^^^^^^^^^^^^^^^^^^^^^^^^^^^^^^^^^^^^^^
  File "C:\Users\seraj\OneDrive\Desktop\gym_management1\payment\views.py", line 294, in payment_success
    payment = Payment.objects.create(
              ^^^^^^^^^^^^^^^^^^^^^^^
  File "C:\Users\seraj\.virtualenvs\ml_project-fwWSGRpw\Lib\site-packages\django\db\models\manager.py", line 87, in manager_method
    return getattr(self.get_queryset(), name)(*args, **kwargs)
           ^^^^^^^^^^^^^^^^^^^^^^^^^^^^^^^^^^^^^^^^^^^^^^^^^^^
  File "C:\Users\seraj\.virtualenvs\ml_project-fwWSGRpw\Lib\site-packages\django\db\models\query.py", line 679, in create
    obj.save(force_insert=True, using=self.db)
  File "C:\Users\seraj\.virtualenvs\ml_project-fwWSGRpw\Lib\site-packages\django\db\models\base.py", line 891, in save
    self.save_base(
  File "C:\Users\seraj\.virtualenvs\ml_project-fwWSGRpw\Lib\site-packages\django\db\models\base.py", line 997, in save_base
    updated = self._save_table(
              ^^^^^^^^^^^^^^^^^
  File "C:\Users\seraj\.virtualenvs\ml_project-fwWSGRpw\Lib\site-packages\django\db\models\base.py", line 1160, in _save_table
    results = self._do_insert(
              ^^^^^^^^^^^^^^^^
  File "C:\Users\seraj\.virtualenvs\ml_project-fwWSGRpw\Lib\site-packages\django\db\models\base.py", line 1201, in _do_insert
    return manager._insert(
           ^^^^^^^^^^^^^^^^
  File "C:\Users\seraj\.virtualenvs\ml_project-fwWSGRpw\Lib\site-packages\django\db\models\manager.py", line 87, in manager_method
    return getattr(self.get_queryset(), name)(*args, **kwargs)
           ^^^^^^^^^^^^^^^^^^^^^^^^^^^^^^^^^^^^^^^^^^^^^^^^^^^
  File "C:\Users\seraj\.virtualenvs\ml_project-fwWSGRpw\Lib\site-packages\django\db\models\query.py", line 1847, in _insert
    return query.get_compiler(using=using).execute_sql(returning_fields)
           ^^^^^^^^^^^^^^^^^^^^^^^^^^^^^^^^^^^^^^^^^^^^^^^^^^^^^^^^^^^^^
  File "C:\Users\seraj\.virtualenvs\ml_project-fwWSGRpw\Lib\site-packages\django\db\models\sql\compiler.py", line 1836, in execute_sql
    cursor.execute(sql, params)
  File "C:\Users\seraj\.virtualenvs\ml_project-fwWSGRpw\Lib\site-packages\django\db\backends\utils.py", line 122, in execute
    return super().execute(sql, params)
           ^^^^^^^^^^^^^^^^^^^^^^^^^^^^
  File "C:\Users\seraj\.virtualenvs\ml_project-fwWSGRpw\Lib\site-packages\django\db\backends\utils.py", line 79, in execute
    return self._execute_with_wrappers(
           ^^^^^^^^^^^^^^^^^^^^^^^^^^^^
  File "C:\Users\seraj\.virtualenvs\ml_project-fwWSGRpw\Lib\site-packages\django\db\backends\utils.py", line 92, in _execute_with_wrappers
    return executor(sql, params, many, context)
           ^^^^^^^^^^^^^^^^^^^^^^^^^^^^^^^^^^^^
  File "C:\Users\seraj\.virtualenvs\ml_project-fwWSGRpw\Lib\site-packages\django\db\backends\utils.py", line 100, in _execute
    with self.db.wrap_database_errors:
  File "C:\Users\seraj\.virtualenvs\ml_project-fwWSGRpw\Lib\site-packages\django\db\utils.py", line 91, in __exit__
    raise dj_exc_value.with_traceback(traceback) from exc_value
  File "C:\Users\seraj\.virtualenvs\ml_project-fwWSGRpw\Lib\site-packages\django\db\backends\utils.py", line 105, in _execute
    return self.cursor.execute(sql, params)
           ^^^^^^^^^^^^^^^^^^^^^^^^^^^^^^^^
  File "C:\Users\seraj\.virtualenvs\ml_project-fwWSGRpw\Lib\site-packages\django\db\backends\sqlite3\base.py", line 354, in execute
    return super().execute(query, params)
           ^^^^^^^^^^^^^^^^^^^^^^^^^^^^^^
django.db.utils.IntegrityError: NOT NULL constraint failed: payment_payment.stripe_payment_id
ERROR 2024-10-04 21:40:22,669 basehttp "GET /payment/payment-success/?session_id=cs_test_a1XrW1B9CVGI5vJklBc2NFDyQI9aMeVf5W5tKOizcS0weu02Z1w91nPEG0 HTTP/1.1" 500 178067
ERROR 2024-10-04 21:43:33,556 log Internal Server Error: /payment/payment-success/
Traceback (most recent call last):
  File "C:\Users\seraj\.virtualenvs\ml_project-fwWSGRpw\Lib\site-packages\django\core\handlers\exception.py", line 55, in inner
    response = get_response(request)
               ^^^^^^^^^^^^^^^^^^^^^
  File "C:\Users\seraj\.virtualenvs\ml_project-fwWSGRpw\Lib\site-packages\django\core\handlers\base.py", line 220, in _get_response
    response = response.render()
               ^^^^^^^^^^^^^^^^^
  File "C:\Users\seraj\.virtualenvs\ml_project-fwWSGRpw\Lib\site-packages\django\template\response.py", line 114, in render
    self.content = self.rendered_content
                   ^^^^^^^^^^^^^^^^^^^^^
  File "C:\Users\seraj\.virtualenvs\ml_project-fwWSGRpw\Lib\site-packages\rest_framework\response.py", line 59, in rendered_content
    assert renderer, ".accepted_renderer not set on Response"
AssertionError: .accepted_renderer not set on Response
ERROR 2024-10-04 21:43:33,589 basehttp "GET /payment/payment-success/?session_id=cs_test_a1kQxKY3lKV2wDA3WLYQpCGxpJOol6AOHX42ttGIVa6115xyhmCjWUNgf9 HTTP/1.1" 500 77446
